Workbook

Sheet Horários
A1: Data | B1: Médico | C1: Nº | D1: Chegada | E1: Campo Entrada | F1: Campo Saída | G1: Ret Entrada | H1: Ret Saída | I1: Paqui Entrada | J1: Paqui Saída | K1: OCT Entrada | L1: OCT Saída | M1: Campo (min) | N1: Ret (min) | O1: Paqui (min) | P1: OCT (min) | Q1: Observação
A2: 01/10/2026 | B2: 114 - Erica de Abreu Borges | C2: 1 | D2: 0.27430556 | E2: 0.28333333 | F2: 0.29027778 | G2: 0.34583333 | H2: 0.34722222 | K2: 0.34722222 | L2: 0.35277778 | M2: =IF(AND(E2<>"",F2<>""),ROUND((F2-E2)*1440,0),"") -> 10 | N2: =IF(AND(G2<>"",H2<>""),ROUND((H2-G2)*1440,0),"") -> 2 | O2: =IF(AND(I2<>"",J2<>""),ROUND((J2-I2)*1440,0),"") | P2: =IF(AND(K2<>"",L2<>""),ROUND((L2-K2)*1440,0),"") -> 8
A3: 01/10/2026 | B3: 114 - Erica de Abreu Borges | C3: 2 | D3: 0.28125 | E3: 0.36736111 | F3: 0.37361111 | K3: 0.43819444 | L3: 0.44305556 | M3: =IF(AND(E3<>"",F3<>""),ROUND((F3-E3)*1440,0),"") -> 9 | N3: =IF(AND(G3<>"",H3<>""),ROUND((H3-G3)*1440,0),"") | O3: =IF(AND(I3<>"",J3<>""),ROUND((J3-I3)*1440,0),"") | P3: =IF(AND(K3<>"",L3<>""),ROUND((L3-K3)*1440,0),"") -> 7
A4: 01/10/2026 | B4: 114 - Erica de Abreu Borges | C4: 3 | D4: 0.28472222 | E4: 0.38819444 | F4: 0.39444444 | G4: 0.42708333 | H4: 0.42916667 | I4: 0.42916667 | J4: 0.43055556 | K4: 0.43055556 | L4: 0.43472222 | M4: =IF(AND(E4<>"",F4<>""),ROUND((F4-E4)*1440,0),"") -> 9 | N4: =IF(AND(G4<>"",H4<>""),ROUND((H4-G4)*1440,0),"") -> 3 | O4: =IF(AND(I4<>"",J4<>""),ROUND((J4-I4)*1440,0),"") -> 2 | P4: =IF(AND(K4<>"",L4<>""),ROUND((L4-K4)*1440,0),"") -> 6
A5: 01/10/2026 | B5: 114 - Erica de Abreu Borges | C5: 4 | D5: 0.27291667 | E5: 0.34236111 | F5: 0.34652778 | I5: 0.40625 | J5: 0.40625 | K5: 0.40694444 | L5: 0.40972222 | M5: =IF(AND(E5<>"",F5<>""),ROUND((F5-E5)*1440,0),"") -> 6 | N5: =IF(AND(G5<>"",H5<>""),ROUND((H5-G5)*1440,0),"") | O5: =IF(AND(I5<>"",J5<>""),ROUND((J5-I5)*1440,0),"") -> 0 | P5: =IF(AND(K5<>"",L5<>""),ROUND((L5-K5)*1440,0),"") -> 4 | Q5: Conferir Paqui/OCT
A6: 01/10/2026 | B6: 114 - Erica de Abreu Borges | C6: 5 | D6: 0.30208333 | E6: 0.42638889 | F6: 0.43611111 | G6: 0.44513889 | H6: 0.44652778 | I6: 0.44652778 | J6: 0.44722222 | K6: 0.44722222 | L6: 0.45069444 | M6: =IF(AND(E6<>"",F6<>""),ROUND((F6-E6)*1440,0),"") -> 14 | N6: =IF(AND(G6<>"",H6<>""),ROUND((H6-G6)*1440,0),"") -> 2 | O6: =IF(AND(I6<>"",J6<>""),ROUND((J6-I6)*1440,0),"") -> 1 | P6: =IF(AND(K6<>"",L6<>""),ROUND((L6-K6)*1440,0),"") -> 5 | Q6: Conferir chegada (07:15 ou 07:13)
A7: 01/10/2026 | B7: 114 - Erica de Abreu Borges | C7: 6 | D7: 0.29513889 | E7: 0.41319444 | F7: 0.42083333 | G7: 0.43680556 | H7: 0.43888889 | M7: =IF(AND(E7<>"",F7<>""),ROUND((F7-E7)*1440,0),"") -> 11 | N7: =IF(AND(G7<>"",H7<>""),ROUND((H7-G7)*1440,0),"") -> 3 | O7: =IF(AND(I7<>"",J7<>""),ROUND((J7-I7)*1440,0),"") | P7: =IF(AND(K7<>"",L7<>""),ROUND((L7-K7)*1440,0),"") | Q7: Após Ret ilegível/riscado
A8: 01/10/2026 | B8: 114 - Erica de Abreu Borges | C8: 7 | D8: 0.27430556 | E8: 0.30208333 | F8: 0.31111111 | G8: 0.38125 | H8: 0.38333333 | M8: =IF(AND(E8<>"",F8<>""),ROUND((F8-E8)*1440,0),"") -> 13 | N8: =IF(AND(G8<>"",H8<>""),ROUND((H8-G8)*1440,0),"") -> 3 | O8: =IF(AND(I8<>"",J8<>""),ROUND((J8-I8)*1440,0),"") | P8: =IF(AND(K8<>"",L8<>""),ROUND((L8-K8)*1440,0),"") | Q8: Após Ret ilegível/riscado
A9: 01/10/2026 | B9: 188 - Emilio Rintaro Suzuki Junior | C9: 1 | D9: 0.26388889 | E9: 0.27569444 | F9: 0.27916667 | G9: 0.29375 | H9: 0.29513889 | K9: 0.29652778 | L9: 0.29861111 | M9: =IF(AND(E9<>"",F9<>""),ROUND((F9-E9)*1440,0),"") -> 5 | N9: =IF(AND(G9<>"",H9<>""),ROUND((H9-G9)*1440,0),"") -> 2 | O9: =IF(AND(I9<>"",J9<>""),ROUND((J9-I9)*1440,0),"") | P9: =IF(AND(K9<>"",L9<>""),ROUND((L9-K9)*1440,0),"") -> 3 | Q9: Conferir fim do OCT
A10: 01/10/2026 | B10: 188 - Emilio Rintaro Suzuki Junior | C10: 2 | D10: 0.27013889 | E10: 0.35 | F10: 0.35625 | G10: 0.39583333 | H10: 0.39791667 | I10: 0.39791667 | J10: 0.39861111 | K10: 0.39861111 | L10: 0.40208333 | M10: =IF(AND(E10<>"",F10<>""),ROUND((F10-E10)*1440,0),"") -> 9 | N10: =IF(AND(G10<>"",H10<>""),ROUND((H10-G10)*1440,0),"") -> 3 | O10: =IF(AND(I10<>"",J10<>""),ROUND((J10-I10)*1440,0),"") -> 1 | P10: =IF(AND(K10<>"",L10<>""),ROUND((L10-K10)*1440,0),"") -> 5
A11: 01/10/2026 | B11: 188 - Emilio Rintaro Suzuki Junior | C11: 3 | D11: 0.26527778 | E11: 0.29097222 | F11: 0.30208333 | G11: 0.31944444 | H11: 0.32083333 | K11: 0.32083333 | L11: 0.32708333 | M11: =IF(AND(E11<>"",F11<>""),ROUND((F11-E11)*1440,0),"") -> 16 | N11: =IF(AND(G11<>"",H11<>""),ROUND((H11-G11)*1440,0),"") -> 2 | O11: =IF(AND(I11<>"",J11<>""),ROUND((J11-I11)*1440,0),"") | P11: =IF(AND(K11<>"",L11<>""),ROUND((L11-K11)*1440,0),"") -> 9
A12: 01/10/2026 | B12: 188 - Emilio Rintaro Suzuki Junior | C12: 4 | D12: 0.26319444 | E12: 0.26527778 | F12: 0.27083333 | G12: 0.28611111 | H12: 0.28819444 | K12: 0.28888889 | L12: 0.29166667 | M12: =IF(AND(E12<>"",F12<>""),ROUND((F12-E12)*1440,0),"") -> 8 | N12: =IF(AND(G12<>"",H12<>""),ROUND((H12-G12)*1440,0),"") -> 3 | O12: =IF(AND(I12<>"",J12<>""),ROUND((J12-I12)*1440,0),"") | P12: =IF(AND(K12<>"",L12<>""),ROUND((L12-K12)*1440,0),"") -> 4
A13: 01/10/2026 | B13: 188 - Emilio Rintaro Suzuki Junior | C13: 5 | D13: 0.27222222 | E13: 0.40069444 | F13: 0.40625 | G13: 0.43888889 | H13: 0.44166667 | K13: 0.43472222 | L13: 0.43888889 | M13: =IF(AND(E13<>"",F13<>""),ROUND((F13-E13)*1440,0),"") -> 8 | N13: =IF(AND(G13<>"",H13<>""),ROUND((H13-G13)*1440,0),"") -> 4 | O13: =IF(AND(I13<>"",J13<>""),ROUND((J13-I13)*1440,0),"") | P13: =IF(AND(K13<>"",L13<>""),ROUND((L13-K13)*1440,0),"") -> 6 | Q13: Ret e OCT parecem trocados
A14: 01/10/2026 | B14: 188 - Emilio Rintaro Suzuki Junior | C14: 6 | D14: 0.32222222 | E14: 0.38055556 | F14: 0.38541667 | M14: =IF(AND(E14<>"",F14<>""),ROUND((F14-E14)*1440,0),"") -> 7 | N14: =IF(AND(G14<>"",H14<>""),ROUND((H14-G14)*1440,0),"") | O14: =IF(AND(I14<>"",J14<>""),ROUND((J14-I14)*1440,0),"") | P14: =IF(AND(K14<>"",L14<>""),ROUND((L14-K14)*1440,0),"")
A15: 01/10/2026 | B15: 188 - Emilio Rintaro Suzuki Junior | C15: 7 | D15: 0.26736111 | E15: 0.32291667 | F15: 0.33194444 | G15: 0.36875 | H15: 0.37152778 | K15: 0.37152778 | L15: 0.37638889 | M15: =IF(AND(E15<>"",F15<>""),ROUND((F15-E15)*1440,0),"") -> 13 | N15: =IF(AND(G15<>"",H15<>""),ROUND((H15-G15)*1440,0),"") -> 4 | O15: =IF(AND(I15<>"",J15<>""),ROUND((J15-I15)*1440,0),"") | P15: =IF(AND(K15<>"",L15<>""),ROUND((L15-K15)*1440,0),"") -> 7
A16: 01/10/2026 | B16: 951 - Roberto Marcio Batista Teixeira | C16: 1 | D16: 0.51388889 | E16: 0.56458333 | F16: 0.56944444 | G16: 0.60972222 | H16: 0.61111111 | K16: 0.61111111 | L16: 0.61527778 | M16: =IF(AND(E16<>"",F16<>""),ROUND((F16-E16)*1440,0),"") -> 7 | N16: =IF(AND(G16<>"",H16<>""),ROUND((H16-G16)*1440,0),"") -> 2 | O16: =IF(AND(I16<>"",J16<>""),ROUND((J16-I16)*1440,0),"") | P16: =IF(AND(K16<>"",L16<>""),ROUND((L16-K16)*1440,0),"") -> 6 | Q16: Chegada parece 14:20 no papel
A17: 01/10/2026 | B17: 951 - Roberto Marcio Batista Teixeira | C17: 2 | D17: 0.52638889 | E17: 0.53541667 | F17: 0.54583333 | G17: 0.56666667 | H17: 0.56944444 | K17: 0.5625 | L17: 0.56666667 | M17: =IF(AND(E17<>"",F17<>""),ROUND((F17-E17)*1440,0),"") -> 15 | N17: =IF(AND(G17<>"",H17<>""),ROUND((H17-G17)*1440,0),"") -> 4 | O17: =IF(AND(I17<>"",J17<>""),ROUND((J17-I17)*1440,0),"") | P17: =IF(AND(K17<>"",L17<>""),ROUND((L17-K17)*1440,0),"") -> 6 | Q17: Conferir OCT
A18: 01/10/2026 | B18: 951 - Roberto Marcio Batista Teixeira | C18: 3 | D18: 0.50694444 | E18: 0.52083333 | F18: 0.52847222 | G18: 0.54791667 | H18: 0.54930556 | K18: 0.54375 | L18: 0.54722222 | M18: =IF(AND(E18<>"",F18<>""),ROUND((F18-E18)*1440,0),"") -> 11 | N18: =IF(AND(G18<>"",H18<>""),ROUND((H18-G18)*1440,0),"") -> 2 | O18: =IF(AND(I18<>"",J18<>""),ROUND((J18-I18)*1440,0),"") | P18: =IF(AND(K18<>"",L18<>""),ROUND((L18-K18)*1440,0),"") -> 5 | Q18: Conferir OCT
A19: 01/10/2026 | B19: 951 - Roberto Marcio Batista Teixeira | C19: 4 | D19: 0.60625 | E19: 0.62986111 | F19: 0.63541667 | G19: 0.66111111 | H19: 0.6625 | K19: 0.66319444 | L19: 0.66527778 | M19: =IF(AND(E19<>"",F19<>""),ROUND((F19-E19)*1440,0),"") -> 8 | N19: =IF(AND(G19<>"",H19<>""),ROUND((H19-G19)*1440,0),"") -> 2 | O19: =IF(AND(I19<>"",J19<>""),ROUND((J19-I19)*1440,0),"") | P19: =IF(AND(K19<>"",L19<>""),ROUND((L19-K19)*1440,0),"") -> 3
A20: 01/10/2026 | B20: 8 - Maria Elenir Ferreira Peret | C20: 1 | D20: 0.29583333 | E20: 0.31527778 | F20: 0.32083333 | G20: 0.33402778 | H20: 0.33611111 | K20: 0.33819444 | L20: 0.34166667 | M20: =IF(AND(E20<>"",F20<>""),ROUND((F20-E20)*1440,0),"") -> 8 | N20: =IF(AND(G20<>"",H20<>""),ROUND((H20-G20)*1440,0),"") -> 3 | O20: =IF(AND(I20<>"",J20<>""),ROUND((J20-I20)*1440,0),"") | P20: =IF(AND(K20<>"",L20<>""),ROUND((L20-K20)*1440,0),"") -> 5
A21: 01/10/2026 | B21: 8 - Maria Elenir Ferreira Peret | C21: 2 | D21: 0.2875 | E21: 0.35833333 | F21: 0.36388889 | G21: 0.3875 | H21: 0.38888889 | I21: 0.38888889 | J21: 0.38958333 | K21: 0.38333333 | L21: 0.38680556 | M21: =IF(AND(E21<>"",F21<>""),ROUND((F21-E21)*1440,0),"") -> 8 | N21: =IF(AND(G21<>"",H21<>""),ROUND((H21-G21)*1440,0),"") -> 2 | O21: =IF(AND(I21<>"",J21<>""),ROUND((J21-I21)*1440,0),"") -> 1 | P21: =IF(AND(K21<>"",L21<>""),ROUND((L21-K21)*1440,0),"") -> 5 | Q21: Conferir fim do OCT (09:17?) e Paqui
A22: 01/10/2026 | B22: 8 - Maria Elenir Ferreira Peret | C22: 3 | D22: 0.27291667 | E22: 0.33333333 | F22: 0.33888889 | G22: 0.36180556 | H22: 0.36388889 | I22: 0.36180556 | J22: 0.36388889 | K22: 0.36458333 | L22: 0.36736111 | M22: =IF(AND(E22<>"",F22<>""),ROUND((F22-E22)*1440,0),"") -> 8 | N22: =IF(AND(G22<>"",H22<>""),ROUND((H22-G22)*1440,0),"") -> 3 | O22: =IF(AND(I22<>"",J22<>""),ROUND((J22-I22)*1440,0),"") -> 3 | P22: =IF(AND(K22<>"",L22<>""),ROUND((L22-K22)*1440,0),"") -> 4 | Q22: Conferir início do Ret
A23: 01/10/2026 | B23: 301 - Renata Dias Trindade | C23: 1 | D23: 0.48611111 | E23: 0.49791667 | F23: 0.50555556 | K23: 0.58263889 | L23: 0.58888889 | M23: =IF(AND(E23<>"",F23<>""),ROUND((F23-E23)*1440,0),"") -> 11 | N23: =IF(AND(G23<>"",H23<>""),ROUND((H23-G23)*1440,0),"") | O23: =IF(AND(I23<>"",J23<>""),ROUND((J23-I23)*1440,0),"") | P23: =IF(AND(K23<>"",L23<>""),ROUND((L23-K23)*1440,0),"") -> 9
A24: 02/10/2026 | B24: 188 - Emilio Rintaro Suzuki Junior | C24: 1 | D24: 0.25763889 | E24: 0.26180556 | F24: 0.26875 | G24: 0.27916667 | H24: 0.28055556 | M24: =IF(AND(E24<>"",F24<>""),ROUND((F24-E24)*1440,0),"") -> 10 | N24: =IF(AND(G24<>"",H24<>""),ROUND((H24-G24)*1440,0),"") -> 2 | O24: =IF(AND(I24<>"",J24<>""),ROUND((J24-I24)*1440,0),"") | P24: =IF(AND(K24<>"",L24<>""),ROUND((L24-K24)*1440,0),"") | Q24: Havia um traço após o Ret (Paqui ou OCT?)
A25: 02/10/2026 | B25: 188 - Emilio Rintaro Suzuki Junior | C25: 2 | D25: 0.27083333 | E25: 0.28402778 | F25: 0.29027778 | G25: 0.30347222 | H25: 0.30486111 | K25: 0.30555556 | L25: 0.3125 | M25: =IF(AND(E25<>"",F25<>""),ROUND((F25-E25)*1440,0),"") -> 9 | N25: =IF(AND(G25<>"",H25<>""),ROUND((H25-G25)*1440,0),"") -> 2 | O25: =IF(AND(I25<>"",J25<>""),ROUND((J25-I25)*1440,0),"") | P25: =IF(AND(K25<>"",L25<>""),ROUND((L25-K25)*1440,0),"") -> 10
A26: 02/10/2026 | B26: 188 - Emilio Rintaro Suzuki Junior | C26: 3 | D26: 0.26597222 | E26: 0.27291667 | F26: 0.27847222 | G26: 0.29861111 | H26: 0.30138889 | M26: =IF(AND(E26<>"",F26<>""),ROUND((F26-E26)*1440,0),"") -> 8 | N26: =IF(AND(G26<>"",H26<>""),ROUND((H26-G26)*1440,0),"") -> 4 | O26: =IF(AND(I26<>"",J26<>""),ROUND((J26-I26)*1440,0),"") | P26: =IF(AND(K26<>"",L26<>""),ROUND((L26-K26)*1440,0),"") | Q26: Traço após o Ret
A27: 02/10/2026 | B27: 188 - Emilio Rintaro Suzuki Junior | C27: 4 | D27: 0.28333333 | E27: 0.33819444 | F27: 0.34305556 | G27: 0.36180556 | H27: 0.36319444 | I27: 0.36319444 | J27: 0.36388889 | K27: 0.36458333 | L27: 0.36805556 | M27: =IF(AND(E27<>"",F27<>""),ROUND((F27-E27)*1440,0),"") -> 7 | N27: =IF(AND(G27<>"",H27<>""),ROUND((H27-G27)*1440,0),"") -> 2 | O27: =IF(AND(I27<>"",J27<>""),ROUND((J27-I27)*1440,0),"") -> 1 | P27: =IF(AND(K27<>"",L27<>""),ROUND((L27-K27)*1440,0),"") -> 5 | Q27: Conferir fim do Campo
A28: 02/10/2026 | B28: 188 - Emilio Rintaro Suzuki Junior | C28: 5 | D28: 0.32638889 | E28: 0.46527778 | F28: 0.47152778 | G28: 0.5 | H28: 0.50347222 | K28: 0.50416667 | L28: 0.51111111 | M28: =IF(AND(E28<>"",F28<>""),ROUND((F28-E28)*1440,0),"") -> 9 | N28: =IF(AND(G28<>"",H28<>""),ROUND((H28-G28)*1440,0),"") -> 5 | O28: =IF(AND(I28<>"",J28<>""),ROUND((J28-I28)*1440,0),"") | P28: =IF(AND(K28<>"",L28<>""),ROUND((L28-K28)*1440,0),"") -> 10
A29: 02/10/2026 | B29: 188 - Emilio Rintaro Suzuki Junior | C29: 6 | D29: 0.275 | E29: 0.30416667 | F29: 0.30972222 | G29: 0.32291667 | H29: 0.325 | K29: 0.32638889 | L29: 0.33194444 | M29: =IF(AND(E29<>"",F29<>""),ROUND((F29-E29)*1440,0),"") -> 8 | N29: =IF(AND(G29<>"",H29<>""),ROUND((H29-G29)*1440,0),"") -> 3 | O29: =IF(AND(I29<>"",J29<>""),ROUND((J29-I29)*1440,0),"") | P29: =IF(AND(K29<>"",L29<>""),ROUND((L29-K29)*1440,0),"") -> 8
A30: 02/10/2026 | B30: 188 - Emilio Rintaro Suzuki Junior | C30: 7 | D30: 0.28819444 | E30: 0.36805556 | F30: 0.37430556 | G30: 0.39375 | H30: 0.39513889 | K30: 0.39027778 | L30: 0.39375 | M30: =IF(AND(E30<>"",F30<>""),ROUND((F30-E30)*1440,0),"") -> 9 | N30: =IF(AND(G30<>"",H30<>""),ROUND((H30-G30)*1440,0),"") -> 2 | O30: =IF(AND(I30<>"",J30<>""),ROUND((J30-I30)*1440,0),"") | P30: =IF(AND(K30<>"",L30<>""),ROUND((L30-K30)*1440,0),"") -> 5 | Q30: OCT anterior ao Ret: conferir
A31: 02/10/2026 | B31: 188 - Emilio Rintaro Suzuki Junior | C31: 8 | D31: 0.31875 | E31: 0.45486111 | F31: 0.45972222 | G31: 0.47777778 | H31: 0.47916667 | K31: 0.47916667 | L31: 0.48194444 | M31: =IF(AND(E31<>"",F31<>""),ROUND((F31-E31)*1440,0),"") -> 7 | N31: =IF(AND(G31<>"",H31<>""),ROUND((H31-G31)*1440,0),"") -> 2 | O31: =IF(AND(I31<>"",J31<>""),ROUND((J31-I31)*1440,0),"") | P31: =IF(AND(K31<>"",L31<>""),ROUND((L31-K31)*1440,0),"") -> 4
A32: 02/10/2026 | B32: 188 - Emilio Rintaro Suzuki Junior | C32: 9 | D32: 0.31458333 | E32: 0.4375 | F32: 0.44444444 | G32: 0.46041667 | H32: 0.46111111 | K32: 0.4625 | L32: 0.46597222 | M32: =IF(AND(E32<>"",F32<>""),ROUND((F32-E32)*1440,0),"") -> 10 | N32: =IF(AND(G32<>"",H32<>""),ROUND((H32-G32)*1440,0),"") -> 1 | O32: =IF(AND(I32<>"",J32<>""),ROUND((J32-I32)*1440,0),"") | P32: =IF(AND(K32<>"",L32<>""),ROUND((L32-K32)*1440,0),"") -> 5
A33: 02/10/2026 | B33: 188 - Emilio Rintaro Suzuki Junior | C33: 10 | D33: 0.30694444 | E33: 0.41875 | F33: 0.42430556 | G33: 0.43680556 | H33: 0.43819444 | K33: 0.43819444 | L33: 0.44305556 | M33: =IF(AND(E33<>"",F33<>""),ROUND((F33-E33)*1440,0),"") -> 8 | N33: =IF(AND(G33<>"",H33<>""),ROUND((H33-G33)*1440,0),"") -> 2 | O33: =IF(AND(I33<>"",J33<>""),ROUND((J33-I33)*1440,0),"") | P33: =IF(AND(K33<>"",L33<>""),ROUND((L33-K33)*1440,0),"") -> 7
A34: 02/10/2026 | B34: 188 - Emilio Rintaro Suzuki Junior | C34: 11 | D34: 0.29166667 | E34: 0.38888889 | F34: 0.39583333 | G34: 0.41180556 | H34: 0.41388889 | K34: 0.40694444 | L34: 0.41111111 | M34: =IF(AND(E34<>"",F34<>""),ROUND((F34-E34)*1440,0),"") -> 10 | N34: =IF(AND(G34<>"",H34<>""),ROUND((H34-G34)*1440,0),"") -> 3 | O34: =IF(AND(I34<>"",J34<>""),ROUND((J34-I34)*1440,0),"") | P34: =IF(AND(K34<>"",L34<>""),ROUND((L34-K34)*1440,0),"") -> 6 | Q34: OCT anterior ao Ret: conferir
A35: 02/10/2026 | B35: 101 - Clarice Freire Dayrell de Souza | C35: 1 | D35: 0.28680556 | E35: 0.35069444 | F35: 0.35486111 | G35: 0.37847222 | H35: 0.38055556 | I35: 0.38055556 | J35: 0.38125 | K35: 0.38125 | L35: 0.38402778 | M35: =IF(AND(E35<>"",F35<>""),ROUND((F35-E35)*1440,0),"") -> 6 | N35: =IF(AND(G35<>"",H35<>""),ROUND((H35-G35)*1440,0),"") -> 3 | O35: =IF(AND(I35<>"",J35<>""),ROUND((J35-I35)*1440,0),"") -> 1 | P35: =IF(AND(K35<>"",L35<>""),ROUND((L35-K35)*1440,0),"") -> 4
A36: 02/10/2026 | B36: 101 - Clarice Freire Dayrell de Souza | C36: 2 | D36: 0.29444444 | E36: 0.39930556 | F36: 0.40277778 | K36: 0.42430556 | L36: 0.42777778 | M36: =IF(AND(E36<>"",F36<>""),ROUND((F36-E36)*1440,0),"") -> 5 | N36: =IF(AND(G36<>"",H36<>""),ROUND((H36-G36)*1440,0),"") | O36: =IF(AND(I36<>"",J36<>""),ROUND((J36-I36)*1440,0),"") | P36: =IF(AND(K36<>"",L36<>""),ROUND((L36-K36)*1440,0),"") -> 5
A37: 02/10/2026 | B37: 101 - Clarice Freire Dayrell de Souza | C37: 3 | D37: 0.28333333 | E37: 0.32013889 | F37: 0.32569444 | G37: 0.35486111 | H37: 0.35625 | I37: 0.35694444 | J37: 0.35763889 | K37: 0.35763889 | L37: 0.36111111 | M37: =IF(AND(E37<>"",F37<>""),ROUND((F37-E37)*1440,0),"") -> 8 | N37: =IF(AND(G37<>"",H37<>""),ROUND((H37-G37)*1440,0),"") -> 2 | O37: =IF(AND(I37<>"",J37<>""),ROUND((J37-I37)*1440,0),"") -> 1 | P37: =IF(AND(K37<>"",L37<>""),ROUND((L37-K37)*1440,0),"") -> 5 | Q37: Conferir Ret/Paqui
A38: 02/10/2026 | B38: 101 - Clarice Freire Dayrell de Souza | C38: 4 | D38: 0.29166667 | E38: 0.425 | F38: 0.43194444 | G38: 0.44305556 | H38: 0.44444444 | I38: 0.44513889 | J38: 0.44583333 | K38: 0.44583333 | L38: 0.45069444 | M38: =IF(AND(E38<>"",F38<>""),ROUND((F38-E38)*1440,0),"") -> 10 | N38: =IF(AND(G38<>"",H38<>""),ROUND((H38-G38)*1440,0),"") -> 2 | O38: =IF(AND(I38<>"",J38<>""),ROUND((J38-I38)*1440,0),"") -> 1 | P38: =IF(AND(K38<>"",L38<>""),ROUND((L38-K38)*1440,0),"") -> 7
A39: 02/10/2026 | B39: 101 - Clarice Freire Dayrell de Souza | C39: 5 | D39: 0.33541667 | E39: 0.45138889 | F39: 0.46041667 | G39: 0.47083333 | H39: 0.47291667 | K39: 0.47361111 | L39: 0.47916667 | M39: =IF(AND(E39<>"",F39<>""),ROUND((F39-E39)*1440,0),"") -> 13 | N39: =IF(AND(G39<>"",H39<>""),ROUND((H39-G39)*1440,0),"") -> 3 | O39: =IF(AND(I39<>"",J39<>""),ROUND((J39-I39)*1440,0),"") | P39: =IF(AND(K39<>"",L39<>""),ROUND((L39-K39)*1440,0),"") -> 8 | Q39: Associação com a linha incerta
A40: 02/10/2026 | B40: 101 - Clarice Freire Dayrell de Souza | C40: 6 | D40: 0.3125 | E40: 0.40625 | F40: 0.41041667 | G40: 0.43263889 | H40: 0.43472222 | K40: 0.42847222 | L40: 0.43333333 | M40: =IF(AND(E40<>"",F40<>""),ROUND((F40-E40)*1440,0),"") -> 6 | N40: =IF(AND(G40<>"",H40<>""),ROUND((H40-G40)*1440,0),"") -> 3 | O40: =IF(AND(I40<>"",J40<>""),ROUND((J40-I40)*1440,0),"") | P40: =IF(AND(K40<>"",L40<>""),ROUND((L40-K40)*1440,0),"") -> 7 | Q40: Associação com a linha incerta; OCT antes do Ret
...

Sheet Resumo
A1: Médico | B1: Data | C1: Pacientes
A2: 114 - Erica de Abreu Borges | B2: 01/10/2026 | C2: =COUNTIFS(Horários!$B$2:$B$43,A2,Horários!$A$2:$A$43,B2) -> 7
A3: 188 - Emilio Rintaro Suzuki Junior | B3: 01/10/2026 | C3: =COUNTIFS(Horários!$B$2:$B$43,A3,Horários!$A$2:$A$43,B3) -> 7
A4: 951 - Roberto Marcio Batista Teixeira | B4: 01/10/2026 | C4: =COUNTIFS(Horários!$B$2:$B$43,A4,Horários!$A$2:$A$43,B4) -> 4
A5: 8 - Maria Elenir Ferreira Peret | B5: 01/10/2026 | C5: =COUNTIFS(Horários!$B$2:$B$43,A5,Horários!$A$2:$A$43,B5) -> 3
A6: 301 - Renata Dias Trindade | B6: 01/10/2026 | C6: =COUNTIFS(Horários!$B$2:$B$43,A6,Horários!$A$2:$A$43,B6) -> 1
A7: 188 - Emilio Rintaro Suzuki Junior | B7: 02/10/2026 | C7: =COUNTIFS(Horários!$B$2:$B$43,A7,Horários!$A$2:$A$43,B7) -> 11
A8: 101 - Clarice Freire Dayrell de Souza | B8: 02/10/2026 | C8: =COUNTIFS(Horários!$B$2:$B$43,A8,Horários!$A$2:$A$43,B8) -> 6
A9: 41 - Eduardo de Castro Miranda Diniz | B9: 02/10/2026 | C9: =COUNTIFS(Horários!$B$2:$B$43,A9,Horários!$A$2:$A$43,B9) -> 3
A10: Total | C10: =SUM(C2:C9) -> 42
A12: Fonte: transcrição manual das anotações em vermelho das folhas fotografadas. '–' (célula vazia) = sem anotação ou ilegível. Durações calculadas por fórmula (saída − entrada). Linhas com observação amarela devem ser conferidas no papel.
